Traceback (most recent call last):
  File "d:\OneDrive - LTTS\Desktop\waste\main.py", line 45, in <module>
    main()
  File "d:\OneDrive - LTTS\Desktop\waste\main.py", line 24, in main
    subscription = Subscription(client, 2000, DataChangeHandler())
  File "C:\Users\40020507\AppData\Local\Packages\PythonSoftwareFoundation.Python.3.10_qbz5n2kfra8p0\LocalCache\local-packages\Python310\site-packages\opcua\common\subscription.py", line 93, in __init__
    response = self.server.create_subscription(
TypeError: Client.create_subscription() got an unexpected keyword argument 'ready_callback'

