2023-07-31 13:54:22 Traceback (most recent call last):
2023-07-31 13:54:22   File "/usr/local/lib/python3.9/site-packages/serial/serialposix.py", line 398, in _reconfigure_port
2023-07-31 13:54:22     orig_attr = termios.tcgetattr(self.fd)
2023-07-31 13:54:22 termios.error: (5, 'Input/output error')
2023-07-31 13:54:22 
2023-07-31 13:54:22 During handling of the above exception, another exception occurred:
2023-07-31 13:54:22 
2023-07-31 13:54:22 Traceback (most recent call last):
2023-07-31 13:54:22   File "/app/main.py", line 74, in <module>
2023-07-31 13:54:22     rs485 = minimalmodbus.Instrument(os.getenv('com_port'), SIMULATOR_UNIT_ID)
2023-07-31 13:54:22   File "/usr/local/lib/python3.9/site-packages/minimalmodbus.py", line 225, in __init__
2023-07-31 13:54:22     self.serial = _serialports[port] = serial.Serial(
2023-07-31 13:54:22   File "/usr/local/lib/python3.9/site-packages/serial/serialutil.py", line 244, in __init__
2023-07-31 13:54:22     self.open()
2023-07-31 13:54:22   File "/usr/local/lib/python3.9/site-packages/serial/serialposix.py", line 332, in open
2023-07-31 13:54:22     self._reconfigure_port(force_update=True)
2023-07-31 13:54:22   File "/usr/local/lib/python3.9/site-packages/serial/serialposix.py", line 401, in _reconfigure_port
2023-07-31 13:54:22     raise SerialException("Could not configure port: {}".format(msg))
2023-07-31 13:54:22 serial.serialutil.SerialException: Could not configure port: (5, 'Input/output error')
lrwxrwxrwx 1 root root 10 Jul 31 12:53 /dev/ttyS1 -> /dev/pts/9
sudo x86_64-linux-gnu/diagslave -m rtu /dev/ttyS0
